
#pip._internal.exceptions.HashErrorsã
/Users/test/Documents/ALFORIS FINANCE/06. CRM/V1/crm-backend/temp-venv/lib/python3.12/site-packages/pip/_internal/exceptions.pyµ µ("2*ù
2
∂ ∂()

∂' ∂()
%2"listk
i

∂ ∂()1%
#pip._internal.exceptions.HashErrors"
errors"__id*"

__unknown_file (

%2*
3*a
3
exceptions.py75
∏ ∏(
%1"#pip._internal.exceptions.HashErrors"
∏ ∏(

%1B'%
#pip._internal.exceptions.HashErrorsH